Workbook

Sheet Import_ventas_LODI
A1: client_order_ref | B1: date_order | C1: commitment_date | D1: *//Cliente | E1: Producto | F1: Codigo Valido? | G1: order_line / product_uom_qty | H1: id | I1: partner_id / id | J1: order_line / product_id / id
F2: =IF(E2="","",IF(ISERROR(VLOOKUP(E2,Productos!B:B,1,FALSE)),"MAL","BIEN")) | H2: =IF(A2="","","import_saleorder_"&$A$2&I2&J2) | I2: =_xlfn.IFNA(VLOOKUP(D2,Clientes!A:B,2,0),"") | J2: =_xlfn.IFNA(VLOOKUP(E2,Productos!B:D,3,0),"")
F3: =IF(E3="","",IF(ISERROR(VLOOKUP(E3,Productos!B:B,1,FALSE)),"MAL","BIEN")) | H3: =IF(A3="","","import_saleorder_"&A3&I3&J3) | I3: =_xlfn.IFNA(VLOOKUP(D3,Clientes!A:B,2,0),"") | J3: =_xlfn.IFNA(VLOOKUP(E3,Productos!B:D,3,0),"")
F4: =IF(E4="","",IF(ISERROR(VLOOKUP(E4,Productos!B:B,1,FALSE)),"MAL","BIEN")) | H4: =IF(A4="","","import_saleorder_"&A4&I4&J4) | I4: =_xlfn.IFNA(VLOOKUP(D4,Clientes!A:B,2,0),"") | J4: =_xlfn.IFNA(VLOOKUP(E4,Productos!B:D,3,0),"")
F5: =IF(E5="","",IF(ISERROR(VLOOKUP(E5,Productos!B:B,1,FALSE)),"MAL","BIEN")) | H5: =IF(A5="","","import_saleorder_"&A5&I5&J5) | I5: =_xlfn.IFNA(VLOOKUP(D5,Clientes!A:B,2,0),"") | J5: =_xlfn.IFNA(VLOOKUP(E5,Productos!B:D,3,0),"")
F6: =IF(E6="","",IF(ISERROR(VLOOKUP(E6,Productos!B:B,1,FALSE)),"MAL","BIEN")) | H6: =IF(A6="","","import_saleorder_"&A6&I6&J6) | I6: =_xlfn.IFNA(VLOOKUP(D6,Clientes!A:B,2,0),"") | J6: =_xlfn.IFNA(VLOOKUP(E6,Productos!B:D,3,0),"")
F7: =IF(E7="","",IF(ISERROR(VLOOKUP(E7,Productos!B:B,1,FALSE)),"MAL","BIEN")) | H7: =IF(A7="","","import_saleorder_"&A7&I7&J7) | I7: =_xlfn.IFNA(VLOOKUP(D7,Clientes!A:B,2,0),"") | J7: =_xlfn.IFNA(VLOOKUP(E7,Productos!B:D,3,0),"")
F8: =IF(E8="","",IF(ISERROR(VLOOKUP(E8,Productos!B:B,1,FALSE)),"MAL","BIEN")) | H8: =IF(A8="","","import_saleorder_"&A8&I8&J8) | I8: =_xlfn.IFNA(VLOOKUP(D8,Clientes!A:B,2,0),"") | J8: =_xlfn.IFNA(VLOOKUP(E8,Productos!B:D,3,0),"")
F9: =IF(E9="","",IF(ISERROR(VLOOKUP(E9,Productos!B:B,1,FALSE)),"MAL","BIEN")) | H9: =IF(A9="","","import_saleorder_"&A9&I9&J9) | I9: =_xlfn.IFNA(VLOOKUP(D9,Clientes!A:B,2,0),"") | J9: =_xlfn.IFNA(VLOOKUP(E9,Productos!B:D,3,0),"")
F10: =IF(E10="","",IF(ISERROR(VLOOKUP(E10,Productos!B:B,1,FALSE)),"MAL","BIEN")) | H10: =IF(A10="","","import_saleorder_"&A10&I10&J10) | I10: =_xlfn.IFNA(VLOOKUP(D10,Clientes!A:B,2,0),"") | J10: =_xlfn.IFNA(VLOOKUP(E10,Productos!B:D,3,0),"")
F11: =IF(E11="","",IF(ISERROR(VLOOKUP(E11,Productos!B:B,1,FALSE)),"MAL","BIEN")) | H11: =IF(A11="","","import_saleorder_"&A11&I11&J11) | I11: =_xlfn.IFNA(VLOOKUP(D11,Clientes!A:B,2,0),"") | J11: =_xlfn.IFNA(VLOOKUP(E11,Productos!B:D,3,0),"")
F12: =IF(E12="","",IF(ISERROR(VLOOKUP(E12,Productos!B:B,1,FALSE)),"MAL","BIEN")) | H12: =IF(A12="","","import_saleorder_"&A12&I12&J12) | I12: =_xlfn.IFNA(VLOOKUP(D12,Clientes!A:B,2,0),"") | J12: =_xlfn.IFNA(VLOOKUP(E12,Productos!B:D,3,0),"")
F13: =IF(E13="","",IF(ISERROR(VLOOKUP(E13,Productos!B:B,1,FALSE)),"MAL","BIEN")) | H13: =IF(A13="","","import_saleorder_"&A13&I13&J13) | I13: =_xlfn.IFNA(VLOOKUP(D13,Clientes!A:B,2,0),"") | J13: =_xlfn.IFNA(VLOOKUP(E13,Productos!B:D,3,0),"")
F14: =IF(E14="","",IF(ISERROR(VLOOKUP(E14,Productos!B:B,1,FALSE)),"MAL","BIEN")) | H14: =IF(A14="","","import_saleorder_"&A14&I14&J14) | I14: =_xlfn.IFNA(VLOOKUP(D14,Clientes!A:B,2,0),"") | J14: =_xlfn.IFNA(VLOOKUP(E14,Productos!B:D,3,0),"")
... F3774: =IF(E3774="","",IF(ISERROR(VLOOKUP(E3774,Productos!B:B,1,FALSE)),"MAL","BIEN")) | H3774: =IF(A3774="","","import_saleorder_"&A3774&I3774&J3774) | I3774: =_xlfn.IFNA(VLOOKUP(D3774,Clientes!A:B,2,0),"") | J3774: =_xlfn.IFNA(VLOOKUP(E3774,Productos!B:D,3,0),"")
F3775: =IF(E3775="","",IF(ISERROR(VLOOKUP(E3775,Productos!B:B,1,FALSE)),"MAL","BIEN")) | J3775: =_xlfn.IFNA(VLOOKUP(E3775,Productos!B:D,3,0),"")
F3776: =IF(E3776="","",IF(ISERROR(VLOOKUP(E3776,Productos!B:B,1,FALSE)),"MAL","BIEN")) | J3776: =_xlfn.IFNA(VLOOKUP(E3776,Productos!B:D,3,0),"")
F3777: =IF(E3777="","",IF(ISERROR(VLOOKUP(E3777,Productos!B:B,1,FALSE)),"MAL","BIEN")) | J3777: =_xlfn.IFNA(VLOOKUP(E3777,Productos!B:D,3,0),"")
F3778: =IF(E3778="","",IF(ISERROR(VLOOKUP(E3778,Productos!B:B,1,FALSE)),"MAL","BIEN")) | J3778: =_xlfn.IFNA(VLOOKUP(E3778,Productos!B:D,3,0),"")
F3779: =IF(E3779="","",IF(ISERROR(VLOOKUP(E3779,Productos!B:B,1,FALSE)),"MAL","BIEN")) | J3779: =_xlfn.IFNA(VLOOKUP(E3779,Productos!B:D,3,0),"")
F3780: =IF(E3780="","",IF(ISERROR(VLOOKUP(E3780,Productos!B:B,1,FALSE)),"MAL","BIEN")) | J3780: =_xlfn.IFNA(VLOOKUP(E3780,Productos!B:D,3,0),"")
F3781: =IF(E3781="","",IF(ISERROR(VLOOKUP(E3781,Productos!B:B,1,FALSE)),"MAL","BIEN")) | J3781: =_xlfn.IFNA(VLOOKUP(E3781,Productos!B:D,3,0),"")
F3782: =IF(E3782="","",IF(ISERROR(VLOOKUP(E3782,Productos!B:B,1,FALSE)),"MAL","BIEN")) | J3782: =_xlfn.IFNA(VLOOKUP(E3782,Productos!B:D,3,0),"")
F3783: =IF(E3783="","",IF(ISERROR(VLOOKUP(E3783,Productos!B:B,1,FALSE)),"MAL","BIEN")) | J3783: =_xlfn.IFNA(VLOOKUP(E3783,Productos!B:D,3,0),"")
F3784: =IF(E3784="","",IF(ISERROR(VLOOKUP(E3784,Productos!B:B,1,FALSE)),"MAL","BIEN")) | J3784: =_xlfn.IFNA(VLOOKUP(E3784,Productos!B:D,3,0),"")
F3785: =IF(E3785="","",IF(ISERROR(VLOOKUP(E3785,Productos!B:B,1,FALSE)),"MAL","BIEN")) | J3785: =_xlfn.IFNA(VLOOKUP(E3785,Productos!B:D,3,0),"")
F3786: =IF(E3786="","",IF(ISERROR(VLOOKUP(E3786,Productos!B:B,1,FALSE)),"MAL","BIEN")) | J3786: =_xlfn.IFNA(VLOOKUP(E3786,Productos!B:D,3,0),"")
... F7517: =IF(E7517="","",IF(ISERROR(VLOOKUP(E7517,Productos!B:B,1,FALSE)),"MAL","BIEN")) | J7517: =_xlfn.IFNA(VLOOKUP(E7517,Productos!B:D,3,0),"")

Sheet Clientes
A1: 115 | B1: __export__.res_partner_8904_08670eee
A2: 3S Automatizacion SA de CV | B2: __export__.res_partner_6262_38f0041d
A3: < | B3: __export__.res_partner_8792_bae2b2d9
A4: A J Rod Company Ltd | B4: __export__.res_partner_4925_d36058ff
A5: A. Hartrodt Mexico S.A. de C.V. | B5: __export__.res_partner_7053_a5f48053
A6: A2 Soluciones Industriales SA de CV | B6: __export__.res_partner_7973_7b5b0a42
A7: ABS Group Services de Mexico SA de CV | B7: __export__.res_partner_4934_dc6e0f2c
A8: ABS QE Services de Mexico S de RL de CV | B8: __export__.res_partner_6929_70753ae0
A9: ABT2 SA de CV | B9: __export__.res_partner_4935_0b02d9f0
A10: ACAT Mexicana | B10: __export__.res_partner_8660_ddf3c8b8
A11: ADEK SA de CV | B11: __export__.res_partner_4953_f21f70b0
A12: AG Electronica SAPI de CV | B12: __export__.res_partner_4965_4e3899f6
A13: AOK Valve Stem Seals LTD. | B13: __export__.res_partner_6927_ee4c2a7f
... A3506: ​payables@srcautomotive.com | B3506: __export__.res_partner_7174_364e41c2

Sheet Productos
A1: LODI | B1: Referencia interna | C1: Nombre | D1: ID
B2: 01436-2 | C2: 1045R0050 RED 1/2PLG | D2: __export__.product_product_216381_a015e4c1
B3: 01622-5 | C3: GRID FRAME-REAR, 25-1/4 IN, A SERIES | D3: __export__.product_product_169785_ba9ebaa8
B4: 01622-5-G | C4: GRID FRAME-REAR, 25-1/4 IN, A SERIES | D4: __export__.product_product_169784_58c869ec
B5: 01623-3 | C5: GRID FRAME-FRT 25-1/2 IN, A SERIES | D5: __export__.product_product_169787_794550f4
B6: 01623-3-G | C6: GRID FRAME-FRT 25-1/2 IN, A SERIES | D6: __export__.product_product_169786_ce7f4f07
B7: 01624-1 | C7: GRID FRAME, REAR 29-5/8 IN, 37F | D7: __export__.product_product_169789_87f4b715
B8: 01624-1-G | C8: GRID FRAME, REAR 29-5/8 IN, 37F | D8: __export__.product_product_169788_02b36493
B9: 01626-8 | C9: GRID FRAME-FRT 29-7/8", 37F | D9: __export__.product_product_169791_507fd59e
B10: 01626-8-G | C10: GRID FRAME-FRT 29-7/8", 37F | D10: __export__.product_product_169790_7d4e290e
B11: 01627-6 | C11: GRID FRAME-FRT 36-1/2", 43F | D11: __export__.product_product_169793_859e2fde
B12: 01627-6-G | C12: GRID FRAME-FRT 36-1/2", 43F | D12: __export__.product_product_169792_58956dc8
B13: 01628-4 | C13: GRID FRAME-REAR, 36-1/4 IN, 43F | D13: __export__.product_product_169795_f43c8fd9
... B83: 1001R | C83: 603011-G | D83: __export__.product_product_171836_a9cba5e2
B84: 1002 | C84: 600026-G | D84: __export__.product_product_169962_95e28d3f
B85: 10029 | C85: Acoplamiento Movil CAM6 | D85: __export__.product_product_169741_edd84ea7
B86: 1003 | C86: 629933-G | D86: __export__.product_product_213228_0f000b07
B87: 1003-AZC | C87: C-7N2.4-G | D87: __export__.product_product_246656_f78a7f3d
B88: 1004 | C88: 629900-G | D88: __export__.product_product_179870_26088748
B89: 10044373R | C89: ENSAMBLE AUTOMATICO 10044373R | D89: __export__.product_product_211477_d2a1209a
B90: 1005 | C90: 629901-G | D90: __export__.product_product_179874_421986b1
B91: 1007184 | C91: C-EG350TBI-G | D91: __export__.product_product_188991_c60748cd
B92: 1007185 | C92: C-EG350E-G | D92: __export__.product_product_188954_41a98ec0
B93: 1007187 | C93: C-EG3.1S-G | D93: __export__.product_product_188923_d7735bc4
B94: 1007188 | C94: C-EG2.8P-G | D94: __export__.product_product_188885_4074559e
B95: 1007189 | C95: C-EG4.3-G | D95: __export__.product_product_189007_4aad160f
B96: 1007191 | C96: C-EG2.2-G | D96: __export__.product_product_188857_432dea3f
B97: 1007192 | C97: C-EF302FI-G | D97: __export__.product_product_188690_f33087f0
B98: 1007193 | C98: C-EF302-G | D98: __export__.product_product_188699_25505ac2
B99: 1007194 | C99: C-EF3.0L-G | D99: __export__.product_product_188641_7a6f3630
B100: 1007195 | C100: C-EF2.9-G | D100: __export__.product_product_188588_8ad75ba4
B101: 1007196 | C101: C-EF2.3LBD-G | D101: __export__.product_product_188565_b8d93038
... B167: 1007284 | C167: C-P7VW2.0L-G | D167: __export__.product_product_203791_034b9255
B168: 1007R | C168: 601780-G | D168: __export__.product_product_170471_cf5327b3
B169: 1008-AZC | C169: C-7G2.5-G | D169: __export__.product_product_246854_46f70aa7
B170: 1008R | C170: 629601-G | D170: __export__.product_product_179710_fe67a997
B171: 100978 | C171: TRUNNION ASSEMBLY-LT | D171: __export__.product_product_224113_da1b23ff
B172: 100978-A | C172: TRUNNION ASSEMBLY-LT A | D172: __export__.product_product_246552_9bccc4dc
B173: 100978-B | C173: TRUNNION ASSEMBLY-LT B | D173: __export__.product_product_246553_34bb3902
B174: 100978-C | C174: TRUNNION ASSEMBLY-LT C | D174: __export__.product_product_246554_8a971c2e
...
